<?xml version="1.0"?>
<robot name="simple_arm" xmlns:xacro="http://www.ros.org/wiki/xacro">

  <!-- BASE -->
  <link name="base_link">
    <visual>
      <geometry><box size="0.1 0.1 0.05"/></geometry>
      <material name="gray"><color rgba="0.5 0.5 0.5 1"/></material>
    </visual>
    <collision>
      <geometry><box size="0.1 0.1 0.05"/></geometry>
    </collision>
    <inertial>
      <mass value="1.0"/>
      <inertia ixx="0.01" iyy="0.01" izz="0.01"
               ixy="0" ixz="0" iyz="0"/>
    </inertial>
  </link>

  <!-- JOINT 1 -->
  <joint name="joint1" type="revolute">
    <parent link="base_link"/>
    <child link="link1"/>
    <origin xyz="0 0 0.025"/>
    <axis xyz="0 0 1"/>
    <limit lower="-3.14" upper="3.14" effort="100" velocity="1.0"/>
    <dynamics damping="0.1"/>
  </joint>

  <!-- LINK 1 -->
  <link name="link1">
    <visual>
      <origin xyz="0 0 0.15"/>
      <geometry><cylinder radius="0.03" length="0.3"/></geometry>
      <material name="blue"><color rgba="0.1 0.4 0.8 1"/></material>
    </visual>
    <collision>
      <origin xyz="0 0 0.15"/>
      <geometry><cylinder radius="0.03" length="0.3"/></geometry>
    </collision>
    <inertial>
      <mass value="0.5"/>
      <inertia ixx="0.004" iyy="0.004" izz="0.001"
               ixy="0" ixz="0" iyz="0"/>
    </inertial>
  </link>

  <!-- JOINT 2 -->
  <joint name="joint2" type="revolute">
    <parent link="link1"/>
    <child link="link2"/>
    <origin xyz="0 0 0.3"/>
    <axis xyz="0 1 0"/>
    <limit lower="-1.57" upper="1.57" effort="50" velocity="1.0"/>
    <dynamics damping="0.1"/>
  </joint>

  <!-- LINK 2 -->
  <link name="link2">
    <visual>
      <origin xyz="0 0 0.15"/>
      <geometry><cylinder radius="0.025" length="0.3"/></geometry>
      <material name="orange"><color rgba="0.9 0.5 0.1 1"/></material>
    </visual>
    <collision>
      <origin xyz="0 0 0.15"/>
      <geometry><cylinder radius="0.025" length="0.3"/></geometry>
    </collision>
    <inertial>
      <mass value="0.3"/>
      <inertia ixx="0.003" iyy="0.003" izz="0.001"
               ixy="0" ixz="0" iyz="0"/>
    </inertial>
  </link>

  <!-- JOINT 3 -->
  <joint name="joint3" type="revolute">
    <parent link="link2"/>
    <child link="link3"/>
    <origin xyz="0 0 0.3"/>
    <axis xyz="0 1 0"/>
    <limit lower="-1.57" upper="1.57" effort="30" velocity="1.0"/>
    <dynamics damping="0.1"/>
  </joint>

  <!-- LINK 3 -->
  <link name="link3">
    <visual>
      <origin xyz="0 0 0.1"/>
      <geometry><cylinder radius="0.02" length="0.2"/></geometry>
      <material name="green"><color rgba="0.1 0.8 0.3 1"/></material>
    </visual>
    <collision>
      <origin xyz="0 0 0.1"/>
      <geometry><cylinder radius="0.02" length="0.2"/></geometry>
    </collision>
    <inertial>
      <mass value="0.1"/>
      <inertia ixx="0.001" iyy="0.001" izz="0.0005"
               ixy="0" ixz="0" iyz="0"/>
    </inertial>
  </link>

  <!-- ros2_control hardware interface -->
  <ros2_control name="arm_system" type="system">
    <hardware>
      <plugin>gz_ros2_control/GazeboSimSystem</plugin>
    </hardware>
    <joint name="joint1">
      <command_interface name="position">
        <param name="min">-3.14</param>
        <param name="max">3.14</param>
      </command_interface>
      <state_interface name="position">
        <param name="initial_value">0.0</param>
      </state_interface>
      <state_interface name="velocity"/>
    </joint>
    <joint name="joint2">
      <command_interface name="position">
        <param name="min">-1.57</param>
        <param name="max">1.57</param>
      </command_interface>
      <state_interface name="position">
        <param name="initial_value">0.0</param>
      </state_interface>
      <state_interface name="velocity"/>
    </joint>
    <joint name="joint3">
      <command_interface name="position">
        <param name="min">-1.57</param>
        <param name="max">1.57</param>
      </command_interface>
      <state_interface name="position">
        <param name="initial_value">0.0</param>
      </state_interface>
      <state_interface name="velocity"/>
    </joint>
  </ros2_control>

  <!-- ✅ THIS IS THE KEY MISSING PIECE -->
  <!-- Tells Gazebo to load the ros2_control plugin -->
  <gazebo>
    <plugin filename="gz_ros2_control-system"
            name="gz_ros2_control::GazeboSimROS2ControlPlugin">
      <parameters>$(find arm_description)/config/controllers.yaml</parameters>
    </plugin>
  </gazebo>

</robot>
